Workbook

Sheet Cronograma
A1: Cronograma del proyecto: UAV de ala fija controlado por 4G LTE
A2: Del 16/10/2026 al 15/12/2026 · las barras del Gantt se dibujan solas a partir de Inicio y Fin
A3: Celdas amarillas = editables (Inicio, Fin, Estado). El resto se calcula. Feriados en la hoja "Feriados".
I4: OCTUBRE | Y4: NOVIEMBRE | BC4: DICIEMBRE
I5: S1 | P5: S2 | W5: S3 | AD5: S4 | AK5: S5 | AR5: S6 | AY5: S7 | BF5: S8 | BM5: S9
A6: N° | B6: Fase | C6: Actividad | D6: Inicio | E6: Fin | F6: Días | G6: Entregable / hito | H6: Estado | I6: =DATE(2026,10,16) -> 46311 | J6: =I6+1 -> 46312 | K6: =J6+1 -> 46313 | L6: =K6+1 -> 46314 | M6: =L6+1 -> 46315 | N6: =M6+1 -> 46316 | O6: =N6+1 -> 46317 | P6: =O6+1 -> 46318 | Q6: =P6+1 -> 46319 | ... BQ6: =BP6+1 -> 46371
A7: F1 | C7: PLANIFICACIÓN Y TRÁMITES | D7: =MIN(D8:D10) -> 46311 | E7: =MAX(E8:E10) -> 46339 | F7: =E7-D7+1 -> 29 | G7: =COUNTIF(H8:H10,"Completado")&" de 3 completadas" -> 1 de 3 completadas
A8: 1 | B8: F1 | C8: Revisión de informe aerodinámico, estado del arte y diagramas | D8: 46311 | E8: 46313 | F8: =E8-D8+1 -> 3 | G8: Documentos base listos | H8: Completado
A9: 2 | B9: F1 | C9: Lista de materiales y compra de faltantes (módem 4G + SIM, UBEC, Depron, sensores) | D9: 46314 | E9: 46321 | F9: =E9-D9+1 -> 8 | G9: Materiales en mano | H9: Pendiente
A10: 3 | B10: F1 | C10: Trámite DGAC: registro del RPAS y permiso de la zona de vuelo | D10: 46314 | E10: 46339 | F10: =E10-D10+1 -> 26 | G10: Constancia de registro | H10: Pendiente
A11: F2 | C11: CONSTRUCCIÓN DEL UAV | D11: =MIN(D12:D15) -> 46316 | E11: =MAX(E12:E15) -> 46334 | F11: =E11-D11+1 -> 19 | G11: =COUNTIF(H12:H15,"Completado")&" de 4 completadas" -> 0 de 4 completadas
A12: 4 | B12: F2 | C12: Construcción de alas, góndola y botalones | D12: 46316 | E12: 46327 | F12: =E12-D12+1 -> 12 | G12: Estructura terminada | H12: Pendiente
A13: 5 | B13: F2 | C13: Instalación de servos, motor, ESC y cableado según diagramas | D13: 46325 | E13: 46331 | F13: =E13-D13+1 -> 7 | G13: Aviónica instalada | H13: Pendiente
A14: 6 | B14: F2 | C14: Distribución de energía: UBEC, regulador 5 V y masa común | D14: 46328 | E14: 46332 | F14: =E14-D14+1 -> 5 | G14: Energía probada | H14: Pendiente
A15: 7 | B15: F2 | C15: Centrado (CG) y prueba de superficies en tierra | D15: 46332 | E15: 46334 | F15: =E15-D15+1 -> 3 | G15: Hito: UAV armado | H15: Pendiente
A16: F3 | C16: ELECTRÓNICA Y SOFTWARE | D16: =MIN(D17:D21) -> 46314 | E16: =MAX(E17:E21) -> 46346 | F16: =E16-D16+1 -> 33 | G16: =COUNTIF(H17:H21,"Completado")&" de 5 completadas" -> 0 de 5 completadas
A17: 8 | B17: F3 | C17: Pruebas de banco del Pico: servos, ESC, MPU6050 y failsafe | D17: 46314 | E17: 46325 | F17: =E17-D17+1 -> 12 | G17: main1.py validado | H17: Pendiente
A18: 9 | B18: F3 | C18: Orange Pi + módem 4G + Tailscale; medir latencia | D18: 46321 | E18: 46332 | F18: =E18-D18+1 -> 12 | G18: Enlace 4G operativo | H18: Pendiente
A19: 10 | B19: F3 | C19: Mejoras del código: armado del motor, ROLL_NEUTRO, telemetría de retorno | D19: 46328 | E19: 46341 | F19: =E19-D19+1 -> 14 | G19: Código v2 | H19: Pendiente
A20: 11 | B20: F3 | C20: Integración de sensores (BME280, MQ con divisor) y registro de datos | D20: 46335 | E20: 46346 | F20: =E20-D20+1 -> 12 | G20: Sensores funcionando | H20: Pendiente
A21: 12 | B21: F3 | C21: Prueba integrada en tierra: enlace completo y corte de red | D21: 46335 | E21: 46339 | F21: =E21-D21+1 -> 5 | G21: Hito: enlace 4G validado | H21: Pendiente
A22: F4 | C22: PRUEBAS DE VUELO | D22: =MIN(D23:D27) -> 46340 | E22: =MAX(E23:E27) -> 46360 | F22: =E22-D22+1 -> 21 | G22: =COUNTIF(H23:H27,"Completado")&" de 5 completadas" -> 0 de 5 completadas
A23: 13 | B23: F4 | C23: Pruebas de planeo (lanzamiento a mano sin motor) | D23: 46340 | E23: 46341 | F23: =E23-D23+1 -> 2 | G23: Planeo estable | H23: Pendiente
A24: 14 | B24: F4 | C24: Primeros vuelos en línea de vista a baja altura | D24: 46342 | E24: 46348 | F24: =E24-D24+1 -> 7 | G24: Hito: primeros vuelos | H24: Pendiente
A25: 15 | B25: F4 | C25: Ajuste de ganancias PD, trims y límites | D25: 46344 | E25: 46353 | F25: =E25-D25+1 -> 10 | G25: Parámetros finales | H25: Pendiente
A26: 16 | B26: F4 | C26: Vuelos de misión con sensores y registro de datos | D26: 46351 | E26: 46360 | F26: =E26-D26+1 -> 10 | G26: Hito: datos completos | H26: Pendiente
A27: 17 | B27: F4 | C27: Reserva para reparaciones y vuelos repetidos | D27: 46354 | E27: 46360 | F27: =E27-D27+1 -> 7 | G27: Margen de seguridad | H27: Pendiente
A28: F5 | C28: ANÁLISIS Y TESIS | D28: =MIN(D29:D32) -> 46342 | E28: =MAX(E29:E32) -> 46371 | F28: =E28-D28+1 -> 30 | G28: =COUNTIF(H29:H32,"Completado")&" de 4 completadas" -> 0 de 4 completadas
A29: 18 | B29: F5 | C29: Redacción de capítulos de implementación y resultados | D29: 46342 | E29: 46366 | F29: =E29-D29+1 -> 25 | G29: Borrador de tesis | H29: Pendiente
A30: 19 | B30: F5 | C30: Procesamiento y análisis de datos (latencia, failsafe, sensores) | D30: 46356 | E30: 46363 | F30: =E30-D30+1 -> 8 | G30: Resultados | H30: Pendiente
A31: 20 | B31: F5 | C31: Revisión con el asesor y correcciones | D31: 46366 | E31: 46369 | F31: =E31-D31+1 -> 4 | G31: Tesis corregida | H31: Pendiente
A32: 21 | B32: F5 | C32: Preparación de la sustentación (diapositivas y video) | D32: 46367 | E32: 46371 | F32: =E32-D32+1 -> 5 | G32: Hito: entrega final | H32: Pendiente
C34: Duración total del proyecto (días calendario) | F34: =MAX(E7:E32)-MIN(D7:D32)+1 -> 61
C35: Actividades completadas | F35: =COUNTIF(H7:H32,"Completado")&" / "&COUNTA(A7:A32)-5 -> 1 / 21
C37: Leyenda del Gantt
C38: Planificación y trámites
C39: Construcción del UAV
C40: Electrónica y software
C41: Pruebas de vuelo
C42: Análisis y tesis
...

Sheet Hitos
A1: Hitos del proyecto
A3: N° | B3: Hito | C3: Fecha | D3: Actividad que lo cierra | E3: Estado
A4: 1 | B4: UAV armado | C4: =Cronograma!E15 -> 46334 | D4: =Cronograma!C15 -> Centrado (CG) y prueba de superficies en tierra | E4: =Cronograma!H15 -> Pendiente
A5: 2 | B5: Enlace 4G validado | C5: =Cronograma!E21 -> 46339 | D5: =Cronograma!C21 -> Prueba integrada en tierra: enlace completo y corte de red | E5: =Cronograma!H21 -> Pendiente
A6: 3 | B6: Primeros vuelos | C6: =Cronograma!E24 -> 46348 | D6: =Cronograma!C24 -> Primeros vuelos en línea de vista a baja altura | E6: =Cronograma!H24 -> Pendiente
A7: 4 | B7: Datos completos | C7: =Cronograma!E26 -> 46360 | D7: =Cronograma!C26 -> Vuelos de misión con sensores y registro de datos | E7: =Cronograma!H26 -> Pendiente
A8: 5 | B8: Entrega final | C8: =Cronograma!E32 -> 46371 | D8: =Cronograma!C32 -> Preparación de la sustentación (diapositivas y video) | E8: =Cronograma!H32 -> Pendiente
B10: Fechas y estados enlazados a la hoja Cronograma (texto verde).

Sheet Feriados
A1: Fecha | B1: Feriado nacional (Perú)
A2: 46327 | B2: Todos los Santos
A3: 46364 | B3: Inmaculada Concepción
A4: 46365 | B4: Batalla de Ayacucho
A6: Fuente: calendario oficial de feriados 2026 (El Comercio / gob.pe). Puede agregar días no laborables en A2:A20.
